<mujoco model="touchtest">
  <compiler autolimits="true" eulerseq="xyz" angle="radian" meshdir="assets"/>
  <include file="tacto_common.xml"/>

  <extension>
    <plugin plugin="mujoco.sensor.touch_grid" />
  </extension>
  <contact>
    <!-- enable all contacts between bodies childA and childB -->
    <!-- This is necessary since both can and left_finger belong to the same body.-->
    <!-- Though, in "normal" use cases, that won't be necessary. -->
    <pair geom1="finger_1_left_0" geom2="can_geom"/>
  </contact>

  <option tolerance="1e-8" gravity="0 0 -9.81" timestep="0.002"/>

  <visual>
    <headlight ambient=".7 .7 .7" diffuse=".2 .2 .2" specular="0.1 0.1 0.1" />
    <map znear="0.001" />
    <scale contactwidth=".02" contactheight=".5" />
    <global fovy="4"/>
  </visual>

  <statistic center="0 0 1" extent="1" meansize="0.1" />

  <worldbody>
    <light pos="1 0 .3" dir="-1 0 -.3" />
    <light pos="-1 0 .3" dir="1 0 -.3" />
    <geom name="floor" pos="0 0 0.01" type="plane" size="1 1 .01"/>

    <!-- We nest both the can and left_finger in the same master body to retain the same relative transforms. -->
    <body name="master" pos="0 -0.05 0.2" euler="0 0 0">
      <joint name="master_joint_x" type="hinge" axis="1 0 0" damping="0.1" />
      <joint name="master_joint_y" type="hinge" axis="0 1 0" damping="0.1" />
      <joint name="master_joint_z" type="hinge" axis="0 0 1" damping="0.1" />
      <!-- objects that we intend to touch with digit -->
      <body name="can" pos="-0.03 0.075 0.05" euler="0 0 0" gravcomp="1">
        <!-- For trying out with other meshes, edit the line below accordingly, and also their corresponding mesh file in tacto_common.xml -->
        <!-- For primitives, tacto_common.xml does not affect the loaded mesh. -->
        <!-- These lines are identical except for their respective pos and euler so that the objects are aligned properly. -->
        
        <!-- Primitives -->
        <!-- <geom name="can_geom" type="cylinder" pos="0 0 0.0" size="0.005 0.005" euler="1.571 0 0" rgba=".5 0 .7 1" friction="0.4" /> -->
        <!-- <geom name="can_geom" type="ellipsoid" pos="0 0 -0.003" size="0.005 0.002 0.002" euler="1.571 0 0" rgba=".5 0 .7 1" friction="0.4" /> -->
        <!-- <geom name="can_geom" type="box" pos="0.00065 0 0.0" size="0.003 0.003 0.003" euler="1.571 0 0" rgba=".5 0 .7 1" friction="0.4" /> -->
        <!-- <geom name="can_geom" type="sphere" pos="0 0 0.0" size="0.005" euler="1.571 0 0" rgba=".5 0 .7 1" friction="0.4" /> -->
        <!-- <geom name="can_geom" type="capsule" pos="0 0 0.0" size="0.005 0.005" euler="1.571 0 0" rgba=".5 0 .7 1" friction="0.4" /> -->
        <!-- uv-sphere, bunny, hammer -->
        <geom name="can_geom" type="mesh" mesh="can_mesh" pos="0 0 -0.00" euler="1.571 0.7 0" rgba=".5 0 .7 1" friction="0.4" /> 
        <!-- Happy Buddha (happy.obj) -->
        <!-- <geom name="can_geom" type="mesh" mesh="can_mesh" pos="0 -0.015 -0.0" euler="0 3.142 0" rgba=".5 0 .7 1" friction="0.4" />  -->
        <!-- Armadillo -->
        <!-- <geom name="can_geom" type="mesh" mesh="can_mesh" pos="0 0 -0.00" euler="0 0 0" rgba=".5 0 .7 1" friction="0.4" />  -->
        <!-- Max Planck -->
        <!-- <geom name="can_geom" type="mesh" mesh="can_mesh" pos="0 0 -0.00" euler="0 1.571 0" rgba=".5 0 .7 1" friction="0.4" />  -->
        
        <inertial pos="0 0 0" mass="1" diaginertia="1 1 1" />
        <joint name="zz" type="slide" axis="1 0 0" damping="0.1" range="-0.01 0.01"/>
        <joint name="yy" type="slide" axis="0 1 0" damping="0.1" range="-0.01 0.01"/>
        <joint name="xx" type="slide" axis="0 0 1" damping="0.1" range="-0.01 0.01"/>
      </body>
    
      <body name="left_finger_0" pos="-0.015 0.0095 0.055" euler="1.571 0 0" gravcomp="1">
          <geom mesh="finger_0" class="visual" rgba="0 0.2 0 0.2" />
          <geom mesh="finger_0" class="collision" name="finger_0_left_0" />
          <body name="left_finger_pad">
              <geom mesh="finger_1" class="visual" rgba="0 0 1 0.2" />
              <geom mesh="finger_1" class="collision" name="finger_1_left_0"/>
              <geom class="fingertip_pad_collision_1" name="fingertip_pad_collision_1_left_0_0" friction="2 0.05 0.0001"/>
              <geom class="fingertip_pad_collision_2" name="fingertip_pad_collision_1_left_1_0" friction="2 0.05 0.0001"/>
              <geom class="fingertip_pad_collision_3" name="fingertip_pad_collision_1_left_2_0" friction="2 0.05 0.0001"/>
              <geom class="fingertip_pad_collision_4" name="fingertip_pad_collision_1_left_3_0" friction="2 0.05 0.0001"/>
              <!-- The xy position of the site depends on the mesh that you are placing it under, but this works well for the example one. -->
              <!-- You want the site's orientation to follow the pyrender camera orientation, where -Z points towards the object. -->
              <!-- Calibrated pose for working with Taxim, specifically with digit_gripper fingerpad -->
              <!-- <geom name="visible_digit_surface" type="box" pos="-0.014355 -0.0098 -0.063" size="0.00638 0.002 0.008512" /> -->
              <site name="left_tacto_pad" pos="-0.014355 -0.0098 -0.063" euler="-1.57 0 1.57"/>
          </body>
          <inertial mass="0.015" pos="0 0 0" diaginertia="2.375e-6 2.375e-6 7.5e-7" />
      </body>
    </body>

  </worldbody>
 
  <sensor>
    <plugin name="left_tacto_pad" plugin="mujoco.sensor.touch_grid" objtype="site" objname="left_tacto_pad">
      <!-- Taken from original tacto -->
      <config key="size" value="120 160" /> 
       <!-- Original tacto fov are 60 and 70, but mujoco's touch sensor defines the FOV on one hemisphere, 
            meaning 180 would cover 360 degrees. so we halve it for this one. -->
      <config key="fov" value="30 35" />
      <config key="gamma" value="0" />
      <config key="nchannel" value="3" />
    </plugin>
  </sensor>
</mujoco>